<?xml version="1.0" encoding="utf-8"?>
<!-- This URDF was automatically created by SolidWorks to URDF Exporter! Originally created by Stephen Brawner (brawner@gmail.com) 
     Commit Version: 1.6.0-4-g7f85cfe  Build Version: 1.6.7995.38578
     For more information, please see http://wiki.ros.org/sw_urdf_exporter -->
<robot
  name="nana_model_0602_1729">
  <link
    name="base_link">
    <inertial>
      <origin
        xyz="-0.19796 0.0027374 0.60139"
        rpy="0 0 0" />
      <mass
        value="10.16" />
      <inertia
        ixx="0.14772"
        ixy="-0.00072308"
        ixz="-0.0010102"
        iyy="0.082667"
        iyz="-0.0017807"
        izz="0.11972" />
    </inertial>
    <visual>
      <origin
        xyz="0 0 0"
        rpy="0 0 0" />
      <geometry>
        <mesh
          filename="package://nana_model_0602_1729/meshes/base_link.STL" />
      </geometry>
      <material
        name="">
        <color
          rgba="0.79216 0.81961 0.93333 1" />
      </material>
    </visual>
    <collision>
      <origin
        xyz="0 0 0"
        rpy="0 0 0" />
      <geometry>
        <mesh
          filename="package://nana_model_0602_1729/meshes/base_link.STL" />
      </geometry>
    </collision>
  </link>
  <link
    name="left_wheel_link">
    <inertial>
      <origin
        xyz="4.5759E-07 -1.8023E-07 0.018599"
        rpy="0 0 0" />
      <mass
        value="2" />
      <inertia
        ixx="0.0020255"
        ixy="8.1072E-08"
        ixz="9.548E-08"
        iyy="0.0020255"
        iyz="-1.1946E-07"
        izz="0.0026396" />
    </inertial>
    <visual>
      <origin
        xyz="0 0 0"
        rpy="0 0 0" />
      <geometry>
        <mesh
          filename="package://nana_model_0602_1729/meshes/left_wheel_link.STL" />
      </geometry>
      <material
        name="">
        <color
          rgba="0.79216 0.81961 0.93333 1" />
      </material>
    </visual>
    <collision>
      <origin
        xyz="0 0 0"
        rpy="0 0 0" />
      <geometry>
        <mesh
          filename="package://nana_model_0602_1729/meshes/left_wheel_link.STL" />
      </geometry>
    </collision>
  </link>
  <joint
    name="left_wheel_joint"
    type="continuous">
    <origin
      xyz="0 0.1939 0.010026"
      rpy="-1.5708 0 0" />
    <parent
      link="base_link" />
    <child
      link="left_wheel_link" />
    <axis
      xyz="0 0 1" />
  </joint>
  <link
    name="right_wheel_link">
    <inertial>
      <origin
        xyz="-1.7081E-07 -3.7793E-07 -0.018599"
        rpy="0 0 0" />
      <mass
        value="2" />
      <inertia
        ixx="0.0020255"
        ixy="-5.6522E-08"
        ixz="3.4902E-08"
        iyy="0.0020254"
        iyz="1.4896E-07"
        izz="0.0026396" />
    </inertial>
    <visual>
      <origin
        xyz="0 0 0"
        rpy="0 0 0" />
      <geometry>
        <mesh
          filename="package://nana_model_0602_1729/meshes/right_wheel_link.STL" />
      </geometry>
      <material
        name="">
        <color
          rgba="0.79216 0.81961 0.93333 1" />
      </material>
    </visual>
    <collision>
      <origin
        xyz="0 0 0"
        rpy="0 0 0" />
      <geometry>
        <mesh
          filename="package://nana_model_0602_1729/meshes/right_wheel_link.STL" />
      </geometry>
    </collision>
  </link>
  <joint
    name="right_wheel_joint"
    type="continuous">
    <origin
      xyz="0 -0.1939 0.010025"
      rpy="-1.5708 0 0" />
    <parent
      link="base_link" />
    <child
      link="right_wheel_link" />
    <axis
      xyz="0 0 1" />
  </joint>
  <link
    name="omni_wheel_left_link">
    <inertial>
      <origin
        xyz="-5.8981E-16 -1.0408E-16 0.0125"
        rpy="0 0 0" />
      <mass
        value="1" />
      <inertia
        ixx="8.9061E-06"
        ixy="-9.4163E-10"
        ixz="3.4522E-20"
        iyy="8.9049E-06"
        iyz="-2.1966E-20"
        izz="1.3455E-05" />
    </inertial>
    <visual>
      <origin
        xyz="0 0 0"
        rpy="0 0 0" />
      <geometry>
        <mesh
          filename="package://nana_model_0602_1729/meshes/omni_wheel_left_link.STL" />
      </geometry>
      <material
        name="">
        <color
          rgba="0.74902 0.74902 0.74902 1" />
      </material>
    </visual>
    <collision>
      <origin
        xyz="0 0 0"
        rpy="0 0 0" />
      <geometry>
        <mesh
          filename="package://nana_model_0602_1729/meshes/omni_wheel_left_link.STL" />
      </geometry>
    </collision>
  </link>
  <joint
    name="omni_wheel_left_joint"
    type="continuous">
    <origin
      xyz="-0.38992 0.1545 -0.057449"
      rpy="-1.5708 0 0" />
    <parent
      link="base_link" />
    <child
      link="omni_wheel_left_link" />
    <axis
      xyz="0 0 1" />
  </joint>
  <link
    name="omni_wheel_right_link">
    <inertial>
      <origin
        xyz="1.5786E-16 -1.8041E-16 -0.0125"
        rpy="0 0 0" />
      <mass
        value="1" />
      <inertia
        ixx="8.9056E-06"
        ixy="-1.1209E-09"
        ixz="2.5452E-20"
        iyy="8.9055E-06"
        iyz="-3.3641E-20"
        izz="1.3455E-05" />
    </inertial>
    <visual>
      <origin
        xyz="0 0 0"
        rpy="0 0 0" />
      <geometry>
        <mesh
          filename="package://nana_model_0602_1729/meshes/omni_wheel_right_link.STL" />
      </geometry>
      <material
        name="">
        <color
          rgba="0.74902 0.74902 0.74902 1" />
      </material>
    </visual>
    <collision>
      <origin
        xyz="0 0 0"
        rpy="0 0 0" />
      <geometry>
        <mesh
          filename="package://nana_model_0602_1729/meshes/omni_wheel_right_link.STL" />
      </geometry>
    </collision>
  </link>
  <joint
    name="omni_wheel_right_joint"
    type="continuous">
    <origin
      xyz="-0.38992 -0.1545 -0.057449"
      rpy="-1.5708 0 0" />
    <parent
      link="base_link" />
    <child
      link="omni_wheel_right_link" />
    <axis
      xyz="0 0 1" />
  </joint>
</robot>